<mujoco model="1-link 2-muscle arm">
  <option timestep="0.005" iterations="50" solver="Newton" tolerance="1e-10" gravity="9.81 0 0"/>

  <visual>
    <global offwidth="1920" offheight="1080"/> 
    <rgba haze=".1 .1 .1 1"/>
  </visual>

  <default>
    <joint type="hinge" pos="0 0 0" axis="0 0 1" limited="true" range="0 120" damping="0.1"/>
    <muscle ctrllimited="true" ctrlrange="0 1"/>
  </default>

  <asset>
    <texture type="skybox" builtin="gradient" rgb1="0.6 0.6 0.6" rgb2="0 0 0" width="512" height="512"/>

    <texture name="texplane" type="2d" builtin="checker" rgb1=".25 .25 .25" rgb2=".3 .3 .3" width="512" height="512" mark="cross" markrgb=".8 .8 .8"/>

    <material name="matplane" reflectance="0.3" rgba="1 1 1 1"/>
  </asset>

  <worldbody>
    <geom name="floor" pos="0 0 -0.5" size="0 0 1" type="plane" material="matplane"/>

    <light directional="true" diffuse=".8 .8 .8" specular=".2 .2 .2" pos="0 0 5" dir="0 0 -1"/>
    <camera name="camera_view" pos="-3 0 2.25" xyaxes="0 -1 0 1 0 2" mode="trackcom"/>
    <camera name="camera" pos="0.598 0.016 1.825" xyaxes="0.024 1.000 0.000 -0.997 0.024 0.078"/>

    <body pos="0 0 0">
      <geom name="upper arm" type="capsule" size="0.045" fromto="0 0 0  0.5 0 0" rgba=".5 .1 .1 1"/>
 
      <site name="s1" pos="0.4 0.06 0" size="0.02"/>
      <site name="s2" pos="0.4 -0.06 0" size="0.02"/> 
      <site name="x1" pos="0.5 -0.15 0" size="0.02" rgba="0 .7 0 1" group="1"/>

      <body pos="0.5 0 0">
        <geom name="forearm" type="capsule" size="0.035" fromto="0 0 0  0.5 0 0" rgba=".5 .1 .1 1"/>
        <joint name="elbow"/>
        <geom name="elbow" type="cylinder" pos="0 0 0" size=".08 .05" rgba=".5 .1 .8 .5" mass="0" group="1"/>

        <site name="s3" pos="0.11 0.05 0" size="0.02"/>
        <site name="s4" pos="0.11 -0.05 0" size="0.02"/>
      </body>
    </body>
  </worldbody>

  <tendon> 

    <spatial name="EF" width="0.01">
      <site site="s1"/>
      <geom geom="elbow"/>
      <site site="s3"/>
    </spatial>

    <spatial name="EE" width="0.01">
      <site site="s2"/>
      <geom geom="elbow" sidesite="x1"/>
      <site site="s4"/>
    </spatial>
 
  </tendon>

  <actuator> 
    <muscle name="EF" tendon="EF"/>
    <muscle name="EE" tendon="EE"/> 
  </actuator>
</mujoco>
